<?xml version="1.0"?>
<robot name="my_robot">

  <link name="base_footprint"/>
  <joint name="base_joint" type="fixed">
    <parent link="base_footprint"/>
    <child link="base_link"/>
    <origin xyz="0 0 0.05" rpy="0 0 0"/> </joint>

  <link name="base_link">
    <visual>
      <origin xyz="0 0 0" rpy="0 0 0"/>
      <geometry>
        <mesh filename="package://bot_sim/meshes/Model.stl" scale="0.01 0.01 0.01"/>
      </geometry>
      <material name="grey"><color rgba="0.5 0.5 0.5 1"/></material>
    </visual>

    <collision>
      <origin xyz="0 0 0.55" rpy="0 0 0"/>
      <geometry>
        <box size="0.38 0.38 1.1"/>
      </geometry>
    </collision>

    <inertial>
      <mass value="20.0"/> <origin xyz="0 0 0.1"/> 
      <inertia ixx="0.5" ixy="0" ixz="0" iyy="0.5" iyz="0" izz="0.5"/>
    </inertial>
  </link>

  <joint name="lidar_joint" type="fixed">
    <parent link="base_link"/>
    <child link="laser_frame"/>
    <origin xyz="0 0 1.15" rpy="0 0 0"/>
  </joint>

  <link name="laser_frame">
    <visual>
      <geometry><cylinder radius="0.035" length="0.05"/></geometry>
      <material name="black"/>
    </visual>
    <collision><geometry><cylinder radius="0.035" length="0.05"/></geometry></collision>
    <inertial>
      <mass value="0.1"/>
      <inertia ixx="0.001" ixy="0" ixz="0" iyy="0.001" iyz="0" izz="0.001"/>
    </inertial>
  </link>

  <gazebo reference="laser_frame">
    <sensor type="ray" name="rplidar">
      <pose>0 0 0 0 0 0</pose>
      <visualize>false</visualize>
      <update_rate>10</update_rate>
      <ray>
        <scan>
          <horizontal>
            <samples>360</samples>
            <resolution>1</resolution>
            <min_angle>-3.14</min_angle>
            <max_angle>3.14</max_angle>
          </horizontal>
        </scan>
        <range>
          <min>0.15</min>
          <max>12.0</max>
          <resolution>0.01</resolution>
        </range>
      </ray>
      <plugin name="gazebo_ros_head_rplidar_controller" filename="libgazebo_ros_laser.so">
        <topicName>/scan</topicName>
        <frameName>laser_frame</frameName>
      </plugin>
    </sensor>
  </gazebo>

  <link name="left_wheel">
    <collision>
      <origin xyz="0 0 0" rpy="1.5707 0 0"/>
      <geometry><cylinder radius="0.06" length="0.03"/></geometry> </collision>
    <inertial>
      <mass value="2.0"/>
      <origin xyz="0 0 0"/>
      <inertia ixx="0.01" ixy="0" ixz="0" iyy="0.01" iyz="0" izz="0.01"/>
    </inertial>
  </link>
  <joint name="left_wheel_joint" type="continuous">
    <parent link="base_link"/>
    <child link="left_wheel"/>
    <origin xyz="0 0.20 0" rpy="0 0 0"/> <axis xyz="0 1 0"/>
  </joint>

  <link name="right_wheel">
    <collision>
      <origin xyz="0 0 0" rpy="1.5707 0 0"/>
      <geometry><cylinder radius="0.06" length="0.03"/></geometry>
    </collision>
    <inertial>
      <mass value="2.0"/>
      <origin xyz="0 0 0"/>
      <inertia ixx="0.01" ixy="0" ixz="0" iyy="0.01" iyz="0" izz="0.01"/>
    </inertial>
  </link>
  <joint name="right_wheel_joint" type="continuous">
    <parent link="base_link"/>
    <child link="right_wheel"/>
    <origin xyz="0 -0.20 0" rpy="0 0 0"/> <axis xyz="0 1 0"/>
  </joint>

  <gazebo>
    <plugin name="differential_drive_controller" filename="libgazebo_ros_diff_drive.so">
      <updateRate>20</updateRate>
      <leftJoint>left_wheel_joint</leftJoint>
      <rightJoint>right_wheel_joint</rightJoint>
      <wheelSeparation>0.40</wheelSeparation> <wheelDiameter>0.12</wheelDiameter> <commandTopic>cmd_vel</commandTopic>
      <odometryTopic>odom</odometryTopic>
      <odometryFrame>odom</odometryFrame>
      <robotBaseFrame>base_footprint</robotBaseFrame>
      <publishWheelTF>false</publishWheelTF>
      <publishOdomTF>true</publishOdomTF>
      <publishWheelJointState>true</publishWheelJointState>
    </plugin>
  </gazebo>

</robot>
